Traceback (most recent call last):
  File "/Volumes/zorg/mb312/.virtualenvs/lis-lession/lib/python3.8/site-packages/jupyter_cache/executors/utils.py", line 51, in single_nb_execution
    executenb(
  File "/Volumes/zorg/mb312/.virtualenvs/lis-lession/lib/python3.8/site-packages/nbclient/client.py", line 1204, in execute
    return NotebookClient(nb=nb, resources=resources, km=km, **kwargs).execute()
  File "/Volumes/zorg/mb312/.virtualenvs/lis-lession/lib/python3.8/site-packages/nbclient/util.py", line 84, in wrapped
    return just_run(coro(*args, **kwargs))
  File "/Volumes/zorg/mb312/.virtualenvs/lis-lession/lib/python3.8/site-packages/nbclient/util.py", line 62, in just_run
    return loop.run_until_complete(coro)
  File "/usr/local/opt/python@3.8/Frameworks/Python.framework/Versions/3.8/lib/python3.8/asyncio/base_events.py", line 616, in run_until_complete
    return future.result()
  File "/Volumes/zorg/mb312/.virtualenvs/lis-lession/lib/python3.8/site-packages/nbclient/client.py", line 663, in async_execute
    await self.async_execute_cell(
  File "/Volumes/zorg/mb312/.virtualenvs/lis-lession/lib/python3.8/site-packages/nbclient/client.py", line 965, in async_execute_cell
    await self._check_raise_for_error(cell, cell_index, exec_reply)
  File "/Volumes/zorg/mb312/.virtualenvs/lis-lession/lib/python3.8/site-packages/nbclient/client.py", line 862, in _check_raise_for_error
    raise CellExecutionError.from_cell_and_msg(cell, exec_reply_content)
nbclient.exceptions.CellExecutionError: An error occurred while executing the following cell:
------------------
someone = lprs[lprs['Plate'], '6UZA652']
oak_map = folium.Map(location=OAK_PD_COORDS,
                     tiles='OpenStreetMap',
                     zoom_start=12)
for i, row in someone.iterrows():
    folium.Marker(
        [row['Latitude'], row['Longitude']],
        popup=row['Timestamp'],
        icon=folium.Icon(color=row['Color'], icon='car', prefix='fa')
    ).add_to(oak_map)
------------------

[0;31m---------------------------------------------------------------------------[0m
[0;31mTypeError[0m                                 Traceback (most recent call last)
Input [0;32mIn [8][0m, in [0;36m<cell line: 1>[0;34m()[0m
[0;32m----> 1[0m someone [38;5;241m=[39m [43mlprs[49m[43m[[49m[43mlprs[49m[43m[[49m[38;5;124;43m'[39;49m[38;5;124;43mPlate[39;49m[38;5;124;43m'[39;49m[43m][49m[43m,[49m[43m [49m[38;5;124;43m'[39;49m[38;5;124;43m6UZA652[39;49m[38;5;124;43m'[39;49m[43m][49m
[1;32m      2[0m oak_map [38;5;241m=[39m folium[38;5;241m.[39mMap(location[38;5;241m=[39mOAK_PD_COORDS,
[1;32m      3[0m                      tiles[38;5;241m=[39m[38;5;124m'[39m[38;5;124mOpenStreetMap[39m[38;5;124m'[39m,
[1;32m      4[0m                      zoom_start[38;5;241m=[39m[38;5;241m12[39m)
[1;32m      5[0m [38;5;28;01mfor[39;00m i, row [38;5;129;01min[39;00m someone[38;5;241m.[39miterrows():

File [0;32m/usr/local/lib/python3.8/site-packages/pandas/core/frame.py:3455[0m, in [0;36mDataFrame.__getitem__[0;34m(self, key)[0m
[1;32m   3453[0m [38;5;28;01mif[39;00m [38;5;28mself[39m[38;5;241m.[39mcolumns[38;5;241m.[39mnlevels [38;5;241m>[39m [38;5;241m1[39m:
[1;32m   3454[0m     [38;5;28;01mreturn[39;00m [38;5;28mself[39m[38;5;241m.[39m_getitem_multilevel(key)
[0;32m-> 3455[0m indexer [38;5;241m=[39m [38;5;28;43mself[39;49m[38;5;241;43m.[39;49m[43mcolumns[49m[38;5;241;43m.[39;49m[43mget_loc[49m[43m([49m[43mkey[49m[43m)[49m
[1;32m   3456[0m [38;5;28;01mif[39;00m is_integer(indexer):
[1;32m   3457[0m     indexer [38;5;241m=[39m [indexer]

File [0;32m/usr/local/lib/python3.8/site-packages/pandas/core/indexes/base.py:3361[0m, in [0;36mIndex.get_loc[0;34m(self, key, method, tolerance)[0m
[1;32m   3359[0m casted_key [38;5;241m=[39m [38;5;28mself[39m[38;5;241m.[39m_maybe_cast_indexer(key)
[1;32m   3360[0m [38;5;28;01mtry[39;00m:
[0;32m-> 3361[0m     [38;5;28;01mreturn[39;00m [38;5;28;43mself[39;49m[38;5;241;43m.[39;49m[43m_engine[49m[38;5;241;43m.[39;49m[43mget_loc[49m[43m([49m[43mcasted_key[49m[43m)[49m
[1;32m   3362[0m [38;5;28;01mexcept[39;00m [38;5;167;01mKeyError[39;00m [38;5;28;01mas[39;00m err:
[1;32m   3363[0m     [38;5;28;01mraise[39;00m [38;5;167;01mKeyError[39;00m(key) [38;5;28;01mfrom[39;00m [38;5;21;01merr[39;00m

File [0;32m/usr/local/lib/python3.8/site-packages/pandas/_libs/index.pyx:76[0m, in [0;36mpandas._libs.index.IndexEngine.get_loc[0;34m()[0m

File [0;32m/usr/local/lib/python3.8/site-packages/pandas/_libs/index.pyx:82[0m, in [0;36mpandas._libs.index.IndexEngine.get_loc[0;34m()[0m

[0;31mTypeError[0m: '(0          6HVB598
1          5WVD836
2          6B57142
3          4FSH999
4          6B57142
            ...   
2739682     681XDA
2739683    3WBW276
2739684    6TLG975
2739685    6ULK403
2739686    5WYX367
Name: Plate, Length: 2739687, dtype: object, '6UZA652')' is an invalid key
TypeError: '(0          6HVB598
1          5WVD836
2          6B57142
3          4FSH999
4          6B57142
            ...   
2739682     681XDA
2739683    3WBW276
2739684    6TLG975
2739685    6ULK403
2739686    5WYX367
Name: Plate, Length: 2739687, dtype: object, '6UZA652')' is an invalid key

